ply
format ascii 1.0
comment : MagicaVoxel @ Ephtracy
element vertex 2907
property float x
property float y
property float z
property uchar red
property uchar green
property uchar blue
end_header
31 31 22 240 203 125
0 0 22 240 203 125
31 0 22 240 203 125
0 1 22 240 203 125
31 31 21 240 203 125
30 31 21 240 203 125
29 31 21 240 203 125
28 31 21 240 203 125
27 31 21 240 203 125
26 31 21 240 203 125
25 31 21 240 203 125
24 31 21 240 203 125
23 31 21 240 203 125
22 31 21 240 203 125
21 31 21 240 203 125
20 31 21 240 203 125
19 31 21 240 203 125
18 31 21 240 203 125
17 31 21 240 203 125
16 31 21 240 203 125
15 31 21 240 203 125
27 25 22 240 203 125
13 31 21 240 203 125
12 31 21 240 203 125
11 31 21 240 203 125
10 31 21 240 203 125
9 31 21 240 203 125
8 31 21 240 203 125
7 31 21 240 203 125
6 31 21 240 203 125
5 31 21 240 203 125
0 31 22 240 203 125
31 30 22 240 203 125
4 31 21 240 203 125
3 31 21 240 203 125
2 31 21 240 203 125
1 31 21 240 203 125
0 31 21 240 203 125
31 30 21 240 203 125
30 30 21 240 203 125
29 30 21 240 203 125
28 30 21 240 203 125
27 30 21 240 203 125
26 30 21 240 203 125
25 30 21 240 203 125
24 30 21 240 203 125
23 30 21 240 203 125
22 30 21 240 203 125
21 30 21 240 203 125
20 30 21 240 203 125
19 30 21 240 203 125
18 30 21 240 203 125
17 30 21 240 203 125
16 30 21 240 203 125
15 30 21 240 203 125
14 30 21 240 203 125
13 30 21 240 203 125
12 30 21 240 203 125
11 30 21 240 203 125
10 30 21 240 203 125
9 30 21 240 203 125
8 30 21 240 203 125
7 30 21 240 203 125
0 30 22 240 203 125
31 29 22 240 203 125
6 30 21 240 203 125
5 30 21 240 203 125
4 30 21 240 203 125
3 30 21 240 203 125
2 30 21 240 203 125
1 30 21 240 203 125
0 30 21 240 203 125
31 29 21 240 203 125
30 29 21 240 203 125
29 29 21 240 203 125
28 29 21 240 203 125
27 29 21 240 203 125
26 29 21 240 203 125
25 29 21 240 203 125
24 29 21 240 203 125
23 29 21 240 203 125
22 29 21 240 203 125
21 29 21 240 203 125
20 29 21 240 203 125
19 29 21 240 203 125
18 29 21 240 203 125
17 29 21 240 203 125
16 29 21 240 203 125
15 29 21 240 203 125
14 29 21 240 203 125
13 29 21 240 203 125
12 29 21 240 203 125
11 29 21 240 203 125
10 29 21 240 203 125
9 29 21 240 203 125
0 29 22 240 203 125
31 28 22 240 203 125
8 29 21 240 203 125
7 29 21 240 203 125
6 29 21 240 203 125
5 29 21 240 203 125
4 29 21 240 203 125
3 29 21 240 203 125
2 29 21 240 203 125
1 29 21 240 203 125
0 29 21 240 203 125
31 28 21 240 203 125
30 28 21 240 203 125
29 28 21 240 203 125
28 28 21 240 203 125
27 28 21 240 203 125
26 28 21 240 203 125
25 28 21 240 203 125
24 28 21 240 203 125
23 28 21 240 203 125
22 28 21 240 203 125
21 28 21 240 203 125
20 28 21 240 203 125
19 28 21 240 203 125
18 28 21 240 203 125
17 28 21 240 203 125
16 28 21 240 203 125
15 28 21 240 203 125
14 28 21 240 203 125
13 28 21 240 203 125
12 28 21 240 203 125
11 28 21 240 203 125
0 28 22 240 203 125
31 27 22 240 203 125
10 28 21 240 203 125
9 28 21 240 203 125
8 28 21 240 203 125
7 28 21 240 203 125
6 28 21 240 203 125
5 28 21 240 203 125
4 28 21 240 203 125
3 28 21 240 203 125
2 28 21 240 203 125
1 28 21 240 203 125
0 28 21 240 203 125
31 1 22 240 203 125
0 2 22 240 203 125
31 27 21 240 203 125
30 27 21 240 203 125
29 27 21 240 203 125
28 27 21 240 203 125
27 27 21 240 203 125
26 27 21 240 203 125
25 27 21 240 203 125
24 27 21 240 203 125
23 27 21 240 203 125
22 27 21 240 203 125
21 27 21 240 203 125
20 27 21 240 203 125
19 27 21 240 203 125
18 27 21 240 203 125
17 27 21 240 203 125
16 27 21 240 203 125
15 27 21 240 203 125
0 27 22 240 203 125
4 26 22 240 203 125
5 28 22 240 203 125
13 27 21 240 203 125
12 27 21 240 203 125
0 0 20 240 203 125
1 0 20 240 203 125
2 0 20 240 203 125
3 0 20 240 203 125
4 0 20 240 203 125
5 0 20 240 203 125
6 0 20 240 203 125
7 0 20 240 203 125
8 0 20 240 203 125
9 0 20 240 203 125
10 0 20 240 203 125
11 0 20 240 203 125
12 0 20 240 203 125
13 0 20 240 203 125
14 0 20 240 203 125
15 0 20 240 203 125
16 0 20 240 203 125
17 0 20 240 203 125
18 0 20 240 203 125
19 0 20 240 203 125
20 0 20 240 203 125
21 0 20 240 203 125
22 0 20 240 203 125
23 0 20 240 203 125
24 0 20 240 203 125
25 0 20 240 203 125
26 0 20 240 203 125
27 0 20 240 203 125
28 0 20 240 203 125
29 0 20 240 203 125
30 0 20 240 203 125
31 0 20 240 203 125
11 27 21 240 203 125
10 27 21 240 203 125
9 27 21 240 203 125
8 27 21 240 203 125
7 27 21 240 203 125
6 27 21 240 203 125
5 27 21 240 203 125
4 27 21 240 203 125
0 1 20 240 203 125
1 1 20 240 203 125
2 1 20 240 203 125
3 1 20 240 203 125
4 1 20 240 203 125
5 1 20 240 203 125
6 1 20 240 203 125
7 1 20 240 203 125
8 1 20 240 203 125
9 1 20 240 203 125
10 1 20 240 203 125
11 1 20 240 203 125
12 1 20 240 203 125
13 1 20 240 203 125
14 1 20 240 203 125
15 1 20 240 203 125
16 1 20 240 203 125
17 1 20 240 203 125
18 1 20 240 203 125
19 1 20 240 203 125
20 1 20 240 203 125
21 1 20 240 203 125
22 1 20 240 203 125
23 1 20 240 203 125
24 1 20 240 203 125
25 1 20 240 203 125
26 1 20 240 203 125
27 1 20 240 203 125
28 1 20 240 203 125
29 1 20 240 203 125
30 1 20 240 203 125
31 1 20 240 203 125
3 27 21 240 203 125
2 27 21 240 203 125
1 27 21 240 203 125
0 27 21 240 203 125
31 26 21 240 203 125
30 26 21 240 203 125
22 11 24 44 110 8
28 26 21 240 203 125
0 2 20 240 203 125
1 2 20 240 203 125
2 2 20 240 203 125
3 2 20 240 203 125
4 2 20 240 203 125
5 2 20 240 203 125
6 2 20 240 203 125
7 2 20 240 203 125
8 2 20 240 203 125
9 2 20 240 203 125
10 2 20 240 203 125
11 2 20 240 203 125
12 2 20 240 203 125
13 2 20 240 203 125
14 2 20 240 203 125
15 2 20 240 203 125
16 2 20 240 203 125
17 2 20 240 203 125
18 2 20 240 203 125
19 2 20 240 203 125
20 2 20 240 203 125
21 2 20 240 203 125
22 2 20 240 203 125
23 2 20 240 203 125
24 2 20 240 203 125
25 2 20 240 203 125
26 2 20 240 203 125
27 2 20 240 203 125
28 2 20 240 203 125
29 2 20 240 203 125
30 2 20 240 203 125
31 2 20 240 203 125
27 26 21 240 203 125
26 26 21 240 203 125
25 26 21 240 203 125
24 26 21 240 203 125
23 26 21 240 203 125
22 26 21 240 203 125
21 26 21 240 203 125
20 26 21 240 203 125
0 3 20 240 203 125
1 3 20 240 203 125
2 3 20 240 203 125
3 3 20 240 203 125
4 3 20 240 203 125
5 3 20 240 203 125
6 3 20 240 203 125
7 3 20 240 203 125
8 3 20 240 203 125
9 3 20 240 203 125
10 3 20 240 203 125
11 3 20 240 203 125
12 3 20 240 203 125
13 3 20 240 203 125
14 3 20 240 203 125
15 3 20 240 203 125
16 3 20 240 203 125
17 3 20 240 203 125
18 3 20 240 203 125
19 3 20 240 203 125
20 3 20 240 203 125
21 3 20 240 203 125
22 3 20 240 203 125
23 3 20 240 203 125
24 3 20 240 203 125
25 3 20 240 203 125
26 3 20 240 203 125
27 3 20 240 203 125
28 3 20 240 203 125
29 3 20 240 203 125
30 3 20 240 203 125
31 3 20 240 203 125
19 26 21 240 203 125
18 26 21 240 203 125
17 26 21 240 203 125
24 23 21 240 203 125
31 25 22 240 203 125
16 26 21 240 203 125
15 26 21 240 203 125
14 26 21 240 203 125
0 4 20 240 203 125
1 4 20 240 203 125
2 4 20 240 203 125
3 4 20 240 203 125
4 4 20 240 203 125
5 4 20 240 203 125
6 4 20 240 203 125
7 4 20 240 203 125
8 4 20 240 203 125
9 4 20 240 203 125
10 4 20 240 203 125
11 4 20 240 203 125
12 4 20 240 203 125
13 4 20 240 203 125
14 4 20 240 203 125
15 4 20 240 203 125
16 4 20 240 203 125
17 4 20 240 203 125
18 4 20 240 203 125
19 4 20 240 203 125
20 4 20 240 203 125
21 4 20 240 203 125
22 4 20 240 203 125
23 4 20 240 203 125
24 4 20 240 203 125
25 4 20 240 203 125
26 4 20 240 203 125
27 4 20 240 203 125
28 4 20 240 203 125
29 4 20 240 203 125
30 4 20 240 203 125
31 4 20 240 203 125
13 26 21 240 203 125
12 26 21 240 203 125
11 26 21 240 203 125
10 26 21 240 203 125
9 26 21 240 203 125
8 26 21 240 203 125
7 26 21 240 203 125
6 26 21 240 203 125
0 5 20 240 203 125
1 5 20 240 203 125
2 5 20 240 203 125
3 5 20 240 203 125
4 5 20 240 203 125
5 5 20 240 203 125
6 5 20 240 203 125
7 5 20 240 203 125
8 5 20 240 203 125
9 5 20 240 203 125
10 5 20 240 203 125
11 5 20 240 203 125
12 5 20 240 203 125
13 5 20 240 203 125
14 5 20 240 203 125
15 5 20 240 203 125
16 5 20 240 203 125
17 5 20 240 203 125
18 5 20 240 203 125
19 5 20 240 203 125
20 5 20 240 203 125
21 5 20 240 203 125
22 5 20 240 203 125
23 5 20 240 203 125
24 5 20 240 203 125
25 5 20 240 203 125
26 5 20 240 203 125
27 5 20 240 203 125
28 5 20 240 203 125
29 5 20 240 203 125
30 5 20 240 203 125
31 5 20 240 203 125
5 26 21 240 203 125
4 26 21 240 203 125
3 26 21 240 203 125
2 26 21 240 203 125
1 26 21 240 203 125
0 26 21 240 203 125
31 25 21 240 203 125
30 25 21 240 203 125
0 6 20 240 203 125
1 6 20 240 203 125
2 6 20 240 203 125
3 6 20 240 203 125
4 6 20 240 203 125
5 6 20 240 203 125
6 6 20 240 203 125
7 6 20 240 203 125
8 6 20 240 203 125
9 6 20 240 203 125
10 6 20 240 203 125
11 6 20 240 203 125
12 6 20 240 203 125
13 6 20 240 203 125
14 6 20 240 203 125
15 6 20 240 203 125
16 6 20 240 203 125
17 6 20 240 203 125
18 6 20 240 203 125
19 6 20 240 203 125
20 6 20 240 203 125
21 6 20 240 203 125
22 6 20 240 203 125
23 6 20 240 203 125
24 6 20 240 203 125
25 6 20 240 203 125
26 6 20 240 203 125
27 6 20 240 203 125
28 6 20 240 203 125
29 6 20 240 203 125
30 6 20 240 203 125
31 6 20 240 203 125
29 25 21 240 203 125
28 25 21 240 203 125
27 25 21 240 203 125
26 25 21 240 203 125
25 25 21 240 203 125
24 25 21 240 203 125
23 25 21 240 203 125
22 25 21 240 203 125
0 7 20 240 203 125
1 7 20 240 203 125
2 7 20 240 203 125
3 7 20 240 203 125
4 7 20 240 203 125
5 7 20 240 203 125
6 7 20 240 203 125
7 7 20 240 203 125
8 7 20 240 203 125
9 7 20 240 203 125
10 7 20 240 203 125
11 7 20 240 203 125
12 7 20 240 203 125
13 7 20 240 203 125
14 7 20 240 203 125
15 7 20 240 203 125
16 7 20 240 203 125
17 7 20 240 203 125
18 7 20 240 203 125
19 7 20 240 203 125
20 7 20 240 203 125
21 7 20 240 203 125
22 7 20 240 203 125
23 7 20 240 203 125
24 7 20 240 203 125
25 7 20 240 203 125
26 7 20 240 203 125
27 7 20 240 203 125
28 7 20 240 203 125
29 7 20 240 203 125
30 7 20 240 203 125
31 7 20 240 203 125
21 25 21 240 203 125
20 25 21 240 203 125
19 25 21 240 203 125
0 25 22 240 203 125
31 24 22 240 203 125
18 25 21 240 203 125
17 25 21 240 203 125
16 25 21 240 203 125
0 8 20 240 203 125
1 8 20 240 203 125
2 8 20 240 203 125
3 8 20 240 203 125
4 8 20 240 203 125
5 8 20 240 203 125
6 8 20 240 203 125
7 8 20 240 203 125
8 8 20 240 203 125
9 8 20 240 203 125
10 8 20 240 203 125
11 8 20 240 203 125
12 8 20 240 203 125
13 8 20 240 203 125
14 8 20 240 203 125
15 8 20 240 203 125
16 8 20 240 203 125
17 8 20 240 203 125
18 8 20 240 203 125
19 8 20 240 203 125
20 8 20 240 203 125
21 8 20 240 203 125
22 8 20 240 203 125
23 8 20 240 203 125
24 8 20 240 203 125
25 8 20 240 203 125
26 8 20 240 203 125
27 8 20 240 203 125
28 8 20 240 203 125
29 8 20 240 203 125
30 8 20 240 203 125
31 8 20 240 203 125
15 25 21 240 203 125
14 25 21 240 203 125
13 25 21 240 203 125
12 25 21 240 203 125
11 25 21 240 203 125
10 25 21 240 203 125
9 25 21 240 203 125
8 25 21 240 203 125
0 9 20 240 203 125
1 9 20 240 203 125
2 9 20 240 203 125
3 9 20 240 203 125
4 9 20 240 203 125
5 9 20 240 203 125
6 9 20 240 203 125
7 9 20 240 203 125
8 9 20 240 203 125
9 9 20 240 203 125
10 9 20 240 203 125
11 9 20 240 203 125
12 9 20 240 203 125
13 9 20 240 203 125
14 9 20 240 203 125
15 9 20 240 203 125
16 9 20 240 203 125
17 9 20 240 203 125
18 9 20 240 203 125
19 9 20 240 203 125
20 9 20 240 203 125
21 9 20 240 203 125
22 9 20 240 203 125
23 9 20 240 203 125
24 9 20 240 203 125
25 9 20 240 203 125
26 9 20 240 203 125
27 9 20 240 203 125
28 9 20 240 203 125
29 9 20 240 203 125
30 9 20 240 203 125
31 9 20 240 203 125
7 25 21 240 203 125
6 25 21 240 203 125
5 25 21 240 203 125
4 25 21 240 203 125
3 25 21 240 203 125
2 25 21 240 203 125
1 25 21 240 203 125
0 25 21 240 203 125
0 10 20 240 203 125
1 10 20 240 203 125
2 10 20 240 203 125
3 10 20 240 203 125
4 10 20 240 203 125
5 10 20 240 203 125
6 10 20 240 203 125
7 10 20 240 203 125
8 10 20 240 203 125
9 10 20 240 203 125
10 10 20 240 203 125
11 10 20 240 203 125
12 10 20 240 203 125
13 10 20 240 203 125
14 10 20 240 203 125
15 10 20 240 203 125
16 10 20 240 203 125
17 10 20 240 203 125
18 10 20 240 203 125
19 10 20 240 203 125
20 10 20 240 203 125
21 10 20 240 203 125
22 10 20 240 203 125
23 10 20 240 203 125
24 10 20 240 203 125
25 10 20 240 203 125
26 10 20 240 203 125
27 10 20 240 203 125
28 10 20 240 203 125
29 10 20 240 203 125
30 10 20 240 203 125
31 10 20 240 203 125
31 24 21 240 203 125
30 24 21 240 203 125
29 24 21 240 203 125
28 24 21 240 203 125
27 24 21 240 203 125
26 24 21 240 203 125
25 24 21 240 203 125
24 24 21 240 203 125
0 11 20 240 203 125
1 11 20 240 203 125
2 11 20 240 203 125
3 11 20 240 203 125
4 11 20 240 203 125
5 11 20 240 203 125
6 11 20 240 203 125
7 11 20 240 203 125
8 11 20 240 203 125
9 11 20 240 203 125
10 11 20 240 203 125
11 11 20 240 203 125
12 11 20 240 203 125
13 11 20 240 203 125
14 11 20 240 203 125
15 11 20 240 203 125
16 11 20 240 203 125
17 11 20 240 203 125
18 11 20 240 203 125
19 11 20 240 203 125
20 11 20 240 203 125
21 11 20 240 203 125
22 11 20 240 203 125
23 11 20 240 203 125
24 11 20 240 203 125
25 11 20 240 203 125
26 11 20 240 203 125
27 11 20 240 203 125
28 11 20 240 203 125
29 11 20 240 203 125
30 11 20 240 203 125
31 11 20 240 203 125
23 24 21 240 203 125
22 24 21 240 203 125
21 24 21 240 203 125
0 24 22 240 203 125
31 23 22 240 203 125
20 24 21 240 203 125
19 24 21 240 203 125
18 24 21 240 203 125
0 12 20 240 203 125
1 12 20 240 203 125
2 12 20 240 203 125
3 12 20 240 203 125
4 12 20 240 203 125
5 12 20 240 203 125
6 12 20 240 203 125
7 12 20 240 203 125
8 12 20 240 203 125
9 12 20 240 203 125
10 12 20 240 203 125
11 12 20 240 203 125
12 12 20 240 203 125
13 12 20 240 203 125
14 12 20 240 203 125
15 12 20 240 203 125
16 12 20 240 203 125
17 12 20 240 203 125
18 12 20 240 203 125
19 12 20 240 203 125
20 12 20 240 203 125
21 12 20 240 203 125
22 12 20 240 203 125
23 12 20 240 203 125
24 12 20 240 203 125
25 12 20 240 203 125
26 12 20 240 203 125
27 12 20 240 203 125
28 12 20 240 203 125
29 12 20 240 203 125
30 12 20 240 203 125
31 12 20 240 203 125
17 24 21 240 203 125
16 24 21 240 203 125
15 24 21 240 203 125
14 24 21 240 203 125
13 24 21 240 203 125
12 24 21 240 203 125
11 24 21 240 203 125
10 24 21 240 203 125
0 13 20 240 203 125
1 13 20 240 203 125
2 13 20 240 203 125
3 13 20 240 203 125
4 13 20 240 203 125
5 13 20 240 203 125
6 13 20 240 203 125
7 13 20 240 203 125
8 13 20 240 203 125
9 13 20 240 203 125
10 13 20 240 203 125
11 13 20 240 203 125
12 13 20 240 203 125
13 13 20 240 203 125
14 13 20 240 203 125
15 13 20 240 203 125
16 13 20 240 203 125
17 13 20 240 203 125
18 13 20 240 203 125
19 13 20 240 203 125
20 13 20 240 203 125
21 13 20 240 203 125
22 13 20 240 203 125
23 13 20 240 203 125
24 13 20 240 203 125
25 13 20 240 203 125
26 13 20 240 203 125
27 13 20 240 203 125
28 13 20 240 203 125
29 13 20 240 203 125
30 13 20 240 203 125
31 13 20 240 203 125
9 24 21 240 203 125
8 24 21 240 203 125
7 24 21 240 203 125
6 24 21 240 203 125
5 24 21 240 203 125
4 24 21 240 203 125
3 24 21 240 203 125
2 24 21 240 203 125
0 14 20 240 203 125
1 14 20 240 203 125
2 14 20 240 203 125
3 14 20 240 203 125
4 14 20 240 203 125
5 14 20 240 203 125
6 14 20 240 203 125
7 14 20 240 203 125
8 14 20 240 203 125
9 14 20 240 203 125
10 14 20 240 203 125
11 14 20 240 203 125
12 14 20 240 203 125
13 14 20 240 203 125
14 14 20 240 203 125
15 14 20 240 203 125
16 14 20 240 203 125
17 14 20 240 203 125
18 14 20 240 203 125
19 14 20 240 203 125
20 14 20 240 203 125
21 14 20 240 203 125
22 14 20 240 203 125
23 14 20 240 203 125
24 14 20 240 203 125
25 14 20 240 203 125
26 14 20 240 203 125
27 14 20 240 203 125
28 14 20 240 203 125
29 14 20 240 203 125
30 14 20 240 203 125
31 14 20 240 203 125
1 24 21 240 203 125
0 24 21 240 203 125
31 2 22 240 203 125
23 25 22 240 203 125
31 23 21 240 203 125
30 23 21 240 203 125
29 23 21 240 203 125
28 23 21 240 203 125
0 15 20 240 203 125
1 15 20 240 203 125
2 15 20 240 203 125
3 15 20 240 203 125
4 15 20 240 203 125
5 15 20 240 203 125
6 15 20 240 203 125
7 15 20 240 203 125
8 15 20 240 203 125
9 15 20 240 203 125
10 15 20 240 203 125
11 15 20 240 203 125
12 15 20 240 203 125
13 15 20 240 203 125
14 15 20 240 203 125
15 15 20 240 203 125
16 15 20 240 203 125
17 15 20 240 203 125
18 15 20 240 203 125
19 15 20 240 203 125
20 15 20 240 203 125
21 15 20 240 203 125
22 15 20 240 203 125
23 15 20 240 203 125
24 15 20 240 203 125
25 15 20 240 203 125
26 15 20 240 203 125
27 15 20 240 203 125
28 15 20 240 203 125
29 15 20 240 203 125
30 15 20 240 203 125
31 15 20 240 203 125
27 23 21 240 203 125
26 23 21 240 203 125
25 23 21 240 203 125
0 23 22 240 203 125
31 22 22 240 203 125
11 27 22 240 203 125
23 23 21 240 203 125
22 23 21 240 203 125
0 16 20 240 203 125
1 16 20 240 203 125
2 16 20 240 203 125
3 16 20 240 203 125
4 16 20 240 203 125
5 16 20 240 203 125
6 16 20 240 203 125
7 16 20 240 203 125
8 16 20 240 203 125
9 16 20 240 203 125
10 16 20 240 203 125
11 16 20 240 203 125
12 16 20 240 203 125
13 16 20 240 203 125
14 16 20 240 203 125
15 16 20 240 203 125
16 16 20 240 203 125
17 16 20 240 203 125
18 16 20 240 203 125
19 16 20 240 203 125
20 16 20 240 203 125
21 16 20 240 203 125
22 16 20 240 203 125
23 16 20 240 203 125
24 16 20 240 203 125
25 16 20 240 203 125
26 16 20 240 203 125
27 16 20 240 203 125
28 16 20 240 203 125
29 16 20 240 203 125
30 16 20 240 203 125
31 16 20 240 203 125
21 23 21 240 203 125
20 23 21 240 203 125
19 23 21 240 203 125
18 23 21 240 203 125
17 23 21 240 203 125
16 23 21 240 203 125
15 23 21 240 203 125
14 23 21 240 203 125
0 17 20 240 203 125
1 17 20 240 203 125
2 17 20 240 203 125
3 17 20 240 203 125
4 17 20 240 203 125
5 17 20 240 203 125
6 17 20 240 203 125
7 17 20 240 203 125
8 17 20 240 203 125
9 17 20 240 203 125
10 17 20 240 203 125
11 17 20 240 203 125
12 17 20 240 203 125
13 17 20 240 203 125
14 17 20 240 203 125
15 17 20 240 203 125
16 17 20 240 203 125
17 17 20 240 203 125
18 17 20 240 203 125
19 17 20 240 203 125
20 17 20 240 203 125
21 17 20 240 203 125
22 17 20 240 203 125
23 17 20 240 203 125
24 17 20 240 203 125
25 17 20 240 203 125
26 17 20 240 203 125
27 17 20 240 203 125
28 17 20 240 203 125
29 17 20 240 203 125
30 17 20 240 203 125
31 17 20 240 203 125
13 23 21 240 203 125
12 23 21 240 203 125
11 23 21 240 203 125
10 23 21 240 203 125
9 23 21 240 203 125
8 23 21 240 203 125
7 23 21 240 203 125
6 23 21 240 203 125
0 18 20 240 203 125
1 18 20 240 203 125
2 18 20 240 203 125
3 18 20 240 203 125
4 18 20 240 203 125
5 18 20 240 203 125
6 18 20 240 203 125
7 18 20 240 203 125
8 18 20 240 203 125
9 18 20 240 203 125
10 18 20 240 203 125
11 18 20 240 203 125
12 18 20 240 203 125
13 18 20 240 203 125
14 18 20 240 203 125
15 18 20 240 203 125
16 18 20 240 203 125
17 18 20 240 203 125
18 18 20 240 203 125
19 18 20 240 203 125
20 18 20 240 203 125
21 18 20 240 203 125
22 18 20 240 203 125
23 18 20 240 203 125
24 18 20 240 203 125
25 18 20 240 203 125
26 18 20 240 203 125
27 18 20 240 203 125
28 18 20 240 203 125
29 18 20 240 203 125
30 18 20 240 203 125
31 18 20 240 203 125
5 23 21 240 203 125
4 23 21 240 203 125
3 23 21 240 203 125
2 23 21 240 203 125
1 23 21 240 203 125
0 23 21 240 203 125
31 22 21 240 203 125
30 22 21 240 203 125
0 19 20 240 203 125
1 19 20 240 203 125
2 19 20 240 203 125
3 19 20 240 203 125
4 19 20 240 203 125
5 19 20 240 203 125
6 19 20 240 203 125
7 19 20 240 203 125
8 19 20 240 203 125
9 19 20 240 203 125
10 19 20 240 203 125
11 19 20 240 203 125
12 19 20 240 203 125
13 19 20 240 203 125
14 19 20 240 203 125
15 19 20 240 203 125
16 19 20 240 203 125
17 19 20 240 203 125
18 19 20 240 203 125
19 19 20 240 203 125
20 19 20 240 203 125
21 19 20 240 203 125
22 19 20 240 203 125
23 19 20 240 203 125
24 19 20 240 203 125
25 19 20 240 203 125
26 19 20 240 203 125
27 19 20 240 203 125
28 19 20 240 203 125
29 19 20 240 203 125
30 19 20 240 203 125
31 19 20 240 203 125
29 22 21 240 203 125
28 22 21 240 203 125
27 22 21 240 203 125
0 22 22 240 203 125
31 21 22 240 203 125
26 22 21 240 203 125
25 22 21 240 203 125
24 22 21 240 203 125
0 20 20 240 203 125
1 20 20 240 203 125
2 20 20 240 203 125
3 20 20 240 203 125
4 20 20 240 203 125
5 20 20 240 203 125
6 20 20 240 203 125
7 20 20 240 203 125
8 20 20 240 203 125
9 20 20 240 203 125
10 20 20 240 203 125
11 20 20 240 203 125
12 20 20 240 203 125
13 20 20 240 203 125
14 20 20 240 203 125
15 20 20 240 203 125
16 20 20 240 203 125
17 20 20 240 203 125
18 20 20 240 203 125
19 20 20 240 203 125
20 20 20 240 203 125
21 20 20 240 203 125
22 20 20 240 203 125
23 20 20 240 203 125
24 20 20 240 203 125
25 20 20 240 203 125
26 20 20 240 203 125
27 20 20 240 203 125
28 20 20 240 203 125
29 20 20 240 203 125
30 20 20 240 203 125
31 20 20 240 203 125
23 22 21 240 203 125
22 22 21 240 203 125
21 22 21 240 203 125
20 22 21 240 203 125
19 22 21 240 203 125
18 22 21 240 203 125
17 22 21 240 203 125
16 22 21 240 203 125
0 21 20 240 203 125
1 21 20 240 203 125
2 21 20 240 203 125
3 21 20 240 203 125
4 21 20 240 203 125
5 21 20 240 203 125
6 21 20 240 203 125
7 21 20 240 203 125
8 21 20 240 203 125
9 21 20 240 203 125
10 21 20 240 203 125
11 21 20 240 203 125
12 21 20 240 203 125
13 21 20 240 203 125
14 21 20 240 203 125
15 21 20 240 203 125
16 21 20 240 203 125
17 21 20 240 203 125
18 21 20 240 203 125
19 21 20 240 203 125
20 21 20 240 203 125
21 21 20 240 203 125
22 21 20 240 203 125
23 21 20 240 203 125
24 21 20 240 203 125
25 21 20 240 203 125
26 21 20 240 203 125
27 21 20 240 203 125
28 21 20 240 203 125
29 21 20 240 203 125
30 21 20 240 203 125
31 21 20 240 203 125
15 22 21 240 203 125
14 22 21 240 203 125
13 22 21 240 203 125
12 22 21 240 203 125
11 22 21 240 203 125
10 22 21 240 203 125
9 22 21 240 203 125
8 22 21 240 203 125
0 22 20 240 203 125
1 22 20 240 203 125
2 22 20 240 203 125
3 22 20 240 203 125
4 22 20 240 203 125
5 22 20 240 203 125
6 22 20 240 203 125
7 22 20 240 203 125
8 22 20 240 203 125
9 22 20 240 203 125
10 22 20 240 203 125
11 22 20 240 203 125
12 22 20 240 203 125
13 22 20 240 203 125
14 22 20 240 203 125
15 22 20 240 203 125
16 22 20 240 203 125
17 22 20 240 203 125
18 22 20 240 203 125
19 22 20 240 203 125
20 22 20 240 203 125
21 22 20 240 203 125
22 22 20 240 203 125
23 22 20 240 203 125
24 22 20 240 203 125
25 22 20 240 203 125
26 22 20 240 203 125
27 22 20 240 203 125
28 22 20 240 203 125
29 22 20 240 203 125
30 22 20 240 203 125
31 22 20 240 203 125
7 22 21 240 203 125
6 22 21 240 203 125
5 22 21 240 203 125
4 22 21 240 203 125
3 22 21 240 203 125
2 22 21 240 203 125
1 22 21 240 203 125
0 22 21 240 203 125
0 23 20 240 203 125
1 23 20 240 203 125
2 23 20 240 203 125
3 23 20 240 203 125
4 23 20 240 203 125
5 23 20 240 203 125
6 23 20 240 203 125
7 23 20 240 203 125
8 23 20 240 203 125
9 23 20 240 203 125
10 23 20 240 203 125
11 23 20 240 203 125
12 23 20 240 203 125
13 23 20 240 203 125
14 23 20 240 203 125
15 23 20 240 203 125
16 23 20 240 203 125
17 23 20 240 203 125
18 23 20 240 203 125
19 23 20 240 203 125
20 23 20 240 203 125
21 23 20 240 203 125
22 23 20 240 203 125
23 23 20 240 203 125
24 23 20 240 203 125
25 23 20 240 203 125
26 23 20 240 203 125
27 23 20 240 203 125
28 23 20 240 203 125
29 23 20 240 203 125
30 23 20 240 203 125
31 23 20 240 203 125
31 21 21 240 203 125
30 21 21 240 203 125
29 21 21 240 203 125
0 21 22 240 203 125
31 20 22 240 203 125
28 21 21 240 203 125
27 21 21 240 203 125
26 21 21 240 203 125
0 24 20 240 203 125
1 24 20 240 203 125
2 24 20 240 203 125
3 24 20 240 203 125
4 24 20 240 203 125
5 24 20 240 203 125
6 24 20 240 203 125
7 24 20 240 203 125
8 24 20 240 203 125
9 24 20 240 203 125
10 24 20 240 203 125
11 24 20 240 203 125
12 24 20 240 203 125
13 24 20 240 203 125
14 24 20 240 203 125
15 24 20 240 203 125
16 24 20 240 203 125
17 24 20 240 203 125
18 24 20 240 203 125
19 24 20 240 203 125
20 24 20 240 203 125
21 24 20 240 203 125
22 24 20 240 203 125
23 24 20 240 203 125
24 24 20 240 203 125
25 24 20 240 203 125
26 24 20 240 203 125
27 24 20 240 203 125
28 24 20 240 203 125
29 24 20 240 203 125
30 24 20 240 203 125
31 24 20 240 203 125
25 21 21 240 203 125
24 21 21 240 203 125
23 21 21 240 203 125
22 21 21 240 203 125
21 21 21 240 203 125
20 21 21 240 203 125
19 21 21 240 203 125
18 21 21 240 203 125
0 25 20 240 203 125
1 25 20 240 203 125
2 25 20 240 203 125
3 25 20 240 203 125
4 25 20 240 203 125
5 25 20 240 203 125
6 25 20 240 203 125
7 25 20 240 203 125
8 25 20 240 203 125
9 25 20 240 203 125
10 25 20 240 203 125
11 25 20 240 203 125
12 25 20 240 203 125
13 25 20 240 203 125
14 25 20 240 203 125
15 25 20 240 203 125
16 25 20 240 203 125
17 25 20 240 203 125
18 25 20 240 203 125
19 25 20 240 203 125
20 25 20 240 203 125
21 25 20 240 203 125
22 25 20 240 203 125
23 25 20 240 203 125
24 25 20 240 203 125
25 25 20 240 203 125
26 25 20 240 203 125
27 25 20 240 203 125
28 25 20 240 203 125
29 25 20 240 203 125
30 25 20 240 203 125
31 25 20 240 203 125
17 21 21 240 203 125
16 21 21 240 203 125
15 21 21 240 203 125
14 21 21 240 203 125
13 21 21 240 203 125
12 21 21 240 203 125
11 21 21 240 203 125
10 21 21 240 203 125
0 26 20 240 203 125
1 26 20 240 203 125
2 26 20 240 203 125
3 26 20 240 203 125
4 26 20 240 203 125
5 26 20 240 203 125
6 26 20 240 203 125
7 26 20 240 203 125
8 26 20 240 203 125
9 26 20 240 203 125
10 26 20 240 203 125
11 26 20 240 203 125
12 26 20 240 203 125
13 26 20 240 203 125
14 26 20 240 203 125
15 26 20 240 203 125
16 26 20 240 203 125
17 26 20 240 203 125
18 26 20 240 203 125
19 26 20 240 203 125
20 26 20 240 203 125
21 26 20 240 203 125
22 26 20 240 203 125
23 26 20 240 203 125
24 26 20 240 203 125
25 26 20 240 203 125
26 26 20 240 203 125
27 26 20 240 203 125
28 26 20 240 203 125
29 26 20 240 203 125
30 26 20 240 203 125
31 26 20 240 203 125
9 21 21 240 203 125
8 21 21 240 203 125
7 21 21 240 203 125
6 21 21 240 203 125
5 21 21 240 203 125
4 21 21 240 203 125
3 21 21 240 203 125
2 21 21 240 203 125
0 27 20 240 203 125
1 27 20 240 203 125
2 27 20 240 203 125
3 27 20 240 203 125
4 27 20 240 203 125
5 27 20 240 203 125
6 27 20 240 203 125
7 27 20 240 203 125
8 27 20 240 203 125
9 27 20 240 203 125
10 27 20 240 203 125
11 27 20 240 203 125
12 27 20 240 203 125
13 27 20 240 203 125
14 27 20 240 203 125
15 27 20 240 203 125
16 27 20 240 203 125
17 27 20 240 203 125
18 27 20 240 203 125
19 27 20 240 203 125
20 27 20 240 203 125
21 27 20 240 203 125
22 27 20 240 203 125
23 27 20 240 203 125
24 27 20 240 203 125
25 27 20 240 203 125
26 27 20 240 203 125
27 27 20 240 203 125
28 27 20 240 203 125
29 27 20 240 203 125
30 27 20 240 203 125
31 27 20 240 203 125
1 21 21 240 203 125
0 21 21 240 203 125
31 20 21 240 203 125
0 20 22 240 203 125
5 26 22 240 203 125
30 20 21 240 203 125
29 20 21 240 203 125
28 20 21 240 203 125
0 28 20 240 203 125
1 28 20 240 203 125
2 28 20 240 203 125
3 28 20 240 203 125
4 28 20 240 203 125
5 28 20 240 203 125
6 28 20 240 203 125
7 28 20 240 203 125
8 28 20 240 203 125
9 28 20 240 203 125
10 28 20 240 203 125
11 28 20 240 203 125
12 28 20 240 203 125
13 28 20 240 203 125
14 28 20 240 203 125
15 28 20 240 203 125
16 28 20 240 203 125
17 28 20 240 203 125
18 28 20 240 203 125
19 28 20 240 203 125
20 28 20 240 203 125
21 28 20 240 203 125
22 28 20 240 203 125
23 28 20 240 203 125
24 28 20 240 203 125
25 28 20 240 203 125
26 28 20 240 203 125
27 28 20 240 203 125
28 28 20 240 203 125
29 28 20 240 203 125
30 28 20 240 203 125
31 28 20 240 203 125
27 20 21 240 203 125
26 20 21 240 203 125
25 20 21 240 203 125
24 20 21 240 203 125
23 20 21 240 203 125
22 20 21 240 203 125
21 20 21 240 203 125
20 20 21 240 203 125
0 29 20 240 203 125
1 29 20 240 203 125
2 29 20 240 203 125
3 29 20 240 203 125
4 29 20 240 203 125
5 29 20 240 203 125
6 29 20 240 203 125
7 29 20 240 203 125
8 29 20 240 203 125
9 29 20 240 203 125
10 29 20 240 203 125
11 29 20 240 203 125
12 29 20 240 203 125
13 29 20 240 203 125
14 29 20 240 203 125
15 29 20 240 203 125
16 29 20 240 203 125
17 29 20 240 203 125
18 29 20 240 203 125
19 29 20 240 203 125
20 29 20 240 203 125
21 29 20 240 203 125
22 29 20 240 203 125
23 29 20 240 203 125
24 29 20 240 203 125
25 29 20 240 203 125
26 29 20 240 203 125
27 29 20 240 203 125
28 29 20 240 203 125
29 29 20 240 203 125
30 29 20 240 203 125
31 29 20 240 203 125
19 20 21 240 203 125
18 20 21 240 203 125
17 20 21 240 203 125
16 20 21 240 203 125
15 20 21 240 203 125
14 20 21 240 203 125
13 20 21 240 203 125
12 20 21 240 203 125
0 30 20 240 203 125
1 30 20 240 203 125
2 30 20 240 203 125
3 30 20 240 203 125
4 30 20 240 203 125
5 30 20 240 203 125
6 30 20 240 203 125
7 30 20 240 203 125
8 30 20 240 203 125
9 30 20 240 203 125
10 30 20 240 203 125
11 30 20 240 203 125
12 30 20 240 203 125
13 30 20 240 203 125
14 30 20 240 203 125
15 30 20 240 203 125
16 30 20 240 203 125
17 30 20 240 203 125
18 30 20 240 203 125
19 30 20 240 203 125
20 30 20 240 203 125
21 30 20 240 203 125
22 30 20 240 203 125
23 30 20 240 203 125
24 30 20 240 203 125
25 30 20 240 203 125
26 30 20 240 203 125
27 30 20 240 203 125
28 30 20 240 203 125
29 30 20 240 203 125
30 30 20 240 203 125
31 30 20 240 203 125
11 20 21 240 203 125
10 20 21 240 203 125
9 20 21 240 203 125
8 20 21 240 203 125
7 20 21 240 203 125
6 20 21 240 203 125
5 20 21 240 203 125
4 20 21 240 203 125
0 31 20 240 203 125
1 31 20 240 203 125
2 31 20 240 203 125
3 31 20 240 203 125
4 31 20 240 203 125
5 31 20 240 203 125
6 31 20 240 203 125
7 31 20 240 203 125
8 31 20 240 203 125
9 31 20 240 203 125
10 31 20 240 203 125
11 31 20 240 203 125
12 31 20 240 203 125
13 31 20 240 203 125
14 31 20 240 203 125
15 31 20 240 203 125
16 31 20 240 203 125
17 31 20 240 203 125
18 31 20 240 203 125
19 31 20 240 203 125
20 31 20 240 203 125
21 31 20 240 203 125
22 31 20 240 203 125
23 31 20 240 203 125
24 31 20 240 203 125
25 31 20 240 203 125
26 31 20 240 203 125
27 31 20 240 203 125
28 31 20 240 203 125
29 31 20 240 203 125
30 31 20 240 203 125
31 31 20 240 203 125
3 20 21 240 203 125
2 20 21 240 203 125
1 20 21 240 203 125
9 29 22 240 203 125
6 26 22 240 203 125
0 20 21 240 203 125
31 3 22 240 203 125
29 31 22 240 203 125
31 19 21 240 203 125
30 19 21 240 203 125
29 19 21 240 203 125
28 19 21 240 203 125
27 19 21 240 203 125
26 19 21 240 203 125
25 19 21 240 203 125
24 19 21 240 203 125
23 19 21 240 203 125
22 19 21 240 203 125
21 19 21 240 203 125
20 19 21 240 203 125
19 19 21 240 203 125
18 19 21 240 203 125
17 19 21 240 203 125
16 19 21 240 203 125
15 19 21 240 203 125
14 19 21 240 203 125
13 19 21 240 203 125
12 19 21 240 203 125
11 19 21 240 203 125
10 19 21 240 203 125
9 19 21 240 203 125
8 19 21 240 203 125
7 19 21 240 203 125
6 19 21 240 203 125
5 19 21 240 203 125
0 18 22 240 203 125
31 17 22 240 203 125
4 19 21 240 203 125
3 19 21 240 203 125
2 19 21 240 203 125
1 19 21 240 203 125
0 19 21 240 203 125
31 18 21 240 203 125
30 18 21 240 203 125
29 18 21 240 203 125
28 18 21 240 203 125
27 18 21 240 203 125
26 18 21 240 203 125
25 18 21 240 203 125
24 18 21 240 203 125
23 18 21 240 203 125
22 18 21 240 203 125
21 18 21 240 203 125
20 18 21 240 203 125
19 18 21 240 203 125
18 18 21 240 203 125
17 18 21 240 203 125
16 18 21 240 203 125
15 18 21 240 203 125
14 18 21 240 203 125
13 18 21 240 203 125
12 18 21 240 203 125
11 18 21 240 203 125
10 18 21 240 203 125
9 18 21 240 203 125
8 18 21 240 203 125
7 18 21 240 203 125
0 17 22 240 203 125
31 16 22 240 203 125
6 18 21 240 203 125
5 18 21 240 203 125
4 18 21 240 203 125
3 18 21 240 203 125
2 18 21 240 203 125
1 18 21 240 203 125
0 18 21 240 203 125
31 17 21 240 203 125
30 17 21 240 203 125
29 17 21 240 203 125
28 17 21 240 203 125
27 17 21 240 203 125
26 17 21 240 203 125
25 17 21 240 203 125
24 17 21 240 203 125
23 17 21 240 203 125
22 17 21 240 203 125
21 17 21 240 203 125
20 17 21 240 203 125
19 17 21 240 203 125
18 17 21 240 203 125
17 17 21 240 203 125
16 17 21 240 203 125
15 17 21 240 203 125
14 17 21 240 203 125
13 17 21 240 203 125
12 17 21 240 203 125
11 17 21 240 203 125
10 17 21 240 203 125
9 17 21 240 203 125
0 16 22 240 203 125
31 15 22 240 203 125
8 17 21 240 203 125
7 17 21 240 203 125
6 17 21 240 203 125
5 17 21 240 203 125
4 17 21 240 203 125
3 17 21 240 203 125
2 17 21 240 203 125
1 17 21 240 203 125
0 17 21 240 203 125
31 16 21 240 203 125
30 16 21 240 203 125
29 16 21 240 203 125
28 16 21 240 203 125
27 16 21 240 203 125
26 16 21 240 203 125
25 16 21 240 203 125
24 16 21 240 203 125
23 16 21 240 203 125
22 16 21 240 203 125
21 16 21 240 203 125
20 16 21 240 203 125
19 16 21 240 203 125
18 16 21 240 203 125
17 16 21 240 203 125
16 16 21 240 203 125
15 16 21 240 203 125
14 16 21 240 203 125
13 16 21 240 203 125
12 16 21 240 203 125
11 16 21 240 203 125
0 15 22 240 203 125
31 14 22 240 203 125
10 16 21 240 203 125
9 16 21 240 203 125
8 16 21 240 203 125
7 16 21 240 203 125
6 16 21 240 203 125
5 16 21 240 203 125
4 16 21 240 203 125
3 16 21 240 203 125
2 16 21 240 203 125
1 16 21 240 203 125
0 16 21 240 203 125
31 4 22 240 203 125
28 31 22 240 203 125
31 15 21 240 203 125
30 15 21 240 203 125
29 15 21 240 203 125
28 15 21 240 203 125
27 15 21 240 203 125
26 15 21 240 203 125
25 15 21 240 203 125
24 15 21 240 203 125
23 15 21 240 203 125
22 15 21 240 203 125
21 15 21 240 203 125
20 15 21 240 203 125
19 15 21 240 203 125
18 15 21 240 203 125
17 15 21 240 203 125
16 15 21 240 203 125
15 15 21 240 203 125
0 14 22 240 203 125
31 13 22 240 203 125
14 15 21 240 203 125
30 25 22 240 203 125
12 15 21 240 203 125
11 15 21 240 203 125
10 15 21 240 203 125
9 15 21 240 203 125
8 15 21 240 203 125
7 15 21 240 203 125
6 15 21 240 203 125
5 15 21 240 203 125
4 15 21 240 203 125
3 15 21 240 203 125
2 15 21 240 203 125
1 15 21 240 203 125
0 15 21 240 203 125
31 14 21 240 203 125
30 14 21 240 203 125
29 14 21 240 203 125
28 14 21 240 203 125
27 14 21 240 203 125
26 14 21 240 203 125
25 14 21 240 203 125
24 14 21 240 203 125
23 14 21 240 203 125
22 14 21 240 203 125
21 14 21 240 203 125
20 14 21 240 203 125
19 14 21 240 203 125
18 14 21 240 203 125
17 14 21 240 203 125
0 13 22 240 203 125
31 12 22 240 203 125
16 14 21 240 203 125
15 14 21 240 203 125
14 14 21 240 203 125
13 14 21 240 203 125
12 14 21 240 203 125
11 14 21 240 203 125
10 14 21 240 203 125
9 14 21 240 203 125
8 14 21 240 203 125
7 14 21 240 203 125
6 14 21 240 203 125
5 14 21 240 203 125
4 14 21 240 203 125
3 14 21 240 203 125
2 14 21 240 203 125
1 14 21 240 203 125
0 14 21 240 203 125
31 13 21 240 203 125
30 13 21 240 203 125
29 13 21 240 203 125
28 13 21 240 203 125
27 13 21 240 203 125
26 13 21 240 203 125
25 13 21 240 203 125
24 13 21 240 203 125
23 13 21 240 203 125
22 13 21 240 203 125
21 13 21 240 203 125
20 13 21 240 203 125
19 13 21 240 203 125
0 12 22 240 203 125
31 11 22 240 203 125
18 13 21 240 203 125
17 13 21 240 203 125
16 13 21 240 203 125
15 13 21 240 203 125
14 13 21 240 203 125
13 13 21 240 203 125
12 13 21 240 203 125
11 13 21 240 203 125
10 13 21 240 203 125
9 13 21 240 203 125
8 13 21 240 203 125
7 13 21 240 203 125
6 13 21 240 203 125
5 13 21 240 203 125
4 13 21 240 203 125
3 13 21 240 203 125
2 13 21 240 203 125
1 13 21 240 203 125
0 13 21 240 203 125
31 12 21 240 203 125
30 12 21 240 203 125
29 12 21 240 203 125
28 12 21 240 203 125
27 12 21 240 203 125
26 12 21 240 203 125
25 12 21 240 203 125
24 12 21 240 203 125
23 12 21 240 203 125
22 12 21 240 203 125
21 12 21 240 203 125
0 11 22 240 203 125
31 10 22 240 203 125
20 12 21 240 203 125
19 12 21 240 203 125
18 12 21 240 203 125
17 12 21 240 203 125
16 12 21 240 203 125
15 12 21 240 203 125
14 12 21 240 203 125
13 12 21 240 203 125
12 12 21 240 203 125
11 12 21 240 203 125
10 12 21 240 203 125
9 12 21 240 203 125
8 12 21 240 203 125
7 12 21 240 203 125
6 12 21 240 203 125
5 12 21 240 203 125
4 12 21 240 203 125
3 12 21 240 203 125
2 12 21 240 203 125
1 12 21 240 203 125
0 12 21 240 203 125
14 31 22 240 203 125
27 31 22 240 203 125
31 11 21 240 203 125
30 11 21 240 203 125
29 11 21 240 203 125
28 11 21 240 203 125
27 11 21 240 203 125
26 11 21 240 203 125
25 11 21 240 203 125
0 10 22 240 203 125
31 9 22 240 203 125
24 11 21 240 203 125
23 11 21 240 203 125
22 11 21 240 203 125
21 11 21 240 203 125
20 11 21 240 203 125
19 11 21 240 203 125
18 11 21 240 203 125
17 11 21 240 203 125
16 11 21 240 203 125
15 11 21 240 203 125
14 11 21 240 203 125
13 11 21 240 203 125
12 11 21 240 203 125
11 11 21 240 203 125
10 11 21 240 203 125
9 11 21 240 203 125
8 11 21 240 203 125
7 11 21 240 203 125
6 11 21 240 203 125
5 11 21 240 203 125
4 11 21 240 203 125
3 11 21 240 203 125
2 11 21 240 203 125
1 11 21 240 203 125
0 11 21 240 203 125
31 10 21 240 203 125
30 10 21 240 203 125
29 10 21 240 203 125
28 10 21 240 203 125
27 10 21 240 203 125
26 31 22 240 203 125
31 8 22 240 203 125
26 10 21 240 203 125
25 10 21 240 203 125
24 10 21 240 203 125
0 0 21 240 203 125
1 0 21 240 203 125
2 0 21 240 203 125
3 0 21 240 203 125
4 0 21 240 203 125
5 0 21 240 203 125
6 0 21 240 203 125
7 0 21 240 203 125
8 0 21 240 203 125
9 0 21 240 203 125
10 0 21 240 203 125
11 0 21 240 203 125
12 0 21 240 203 125
13 0 21 240 203 125
14 0 21 240 203 125
15 0 21 240 203 125
16 0 21 240 203 125
17 0 21 240 203 125
18 0 21 240 203 125
19 0 21 240 203 125
20 0 21 240 203 125
21 0 21 240 203 125
22 0 21 240 203 125
23 0 21 240 203 125
24 0 21 240 203 125
25 0 21 240 203 125
26 0 21 240 203 125
27 0 21 240 203 125
28 0 21 240 203 125
29 0 21 240 203 125
30 0 21 240 203 125
31 0 21 240 203 125
23 10 21 240 203 125
22 10 21 240 203 125
21 10 21 240 203 125
20 10 21 240 203 125
19 10 21 240 203 125
18 10 21 240 203 125
17 10 21 240 203 125
16 10 21 240 203 125
0 1 21 240 203 125
1 1 21 240 203 125
2 1 21 240 203 125
3 1 21 240 203 125
4 1 21 240 203 125
5 1 21 240 203 125
6 1 21 240 203 125
7 1 21 240 203 125
8 1 21 240 203 125
9 1 21 240 203 125
10 1 21 240 203 125
11 1 21 240 203 125
12 1 21 240 203 125
13 1 21 240 203 125
14 1 21 240 203 125
15 1 21 240 203 125
16 1 21 240 203 125
17 1 21 240 203 125
18 1 21 240 203 125
19 1 21 240 203 125
20 1 21 240 203 125
21 1 21 240 203 125
22 1 21 240 203 125
23 1 21 240 203 125
24 1 21 240 203 125
25 1 21 240 203 125
26 1 21 240 203 125
27 1 21 240 203 125
28 1 21 240 203 125
29 1 21 240 203 125
30 1 21 240 203 125
31 1 21 240 203 125
15 10 21 240 203 125
14 10 21 240 203 125
13 10 21 240 203 125
12 10 21 240 203 125
11 10 21 240 203 125
10 10 21 240 203 125
9 10 21 240 203 125
8 10 21 240 203 125
0 2 21 240 203 125
1 2 21 240 203 125
2 2 21 240 203 125
3 2 21 240 203 125
4 2 21 240 203 125
5 2 21 240 203 125
6 2 21 240 203 125
7 2 21 240 203 125
8 2 21 240 203 125
9 2 21 240 203 125
10 2 21 240 203 125
11 2 21 240 203 125
12 2 21 240 203 125
13 2 21 240 203 125
14 2 21 240 203 125
15 2 21 240 203 125
16 2 21 240 203 125
17 2 21 240 203 125
18 2 21 240 203 125
19 2 21 240 203 125
20 2 21 240 203 125
21 2 21 240 203 125
22 2 21 240 203 125
23 2 21 240 203 125
24 2 21 240 203 125
25 2 21 240 203 125
26 2 21 240 203 125
27 2 21 240 203 125
28 2 21 240 203 125
29 2 21 240 203 125
30 2 21 240 203 125
31 2 21 240 203 125
7 10 21 240 203 125
6 10 21 240 203 125
5 10 21 240 203 125
4 10 21 240 203 125
3 10 21 240 203 125
2 10 21 240 203 125
1 10 21 240 203 125
0 10 21 240 203 125
0 3 21 240 203 125
1 3 21 240 203 125
2 3 21 240 203 125
3 3 21 240 203 125
4 3 21 240 203 125
5 3 21 240 203 125
6 3 21 240 203 125
7 3 21 240 203 125
8 3 21 240 203 125
9 3 21 240 203 125
10 3 21 240 203 125
11 3 21 240 203 125
12 3 21 240 203 125
13 3 21 240 203 125
14 3 21 240 203 125
15 3 21 240 203 125
16 3 21 240 203 125
17 3 21 240 203 125
18 3 21 240 203 125
19 3 21 240 203 125
20 3 21 240 203 125
21 3 21 240 203 125
22 3 21 240 203 125
23 3 21 240 203 125
24 3 21 240 203 125
25 3 21 240 203 125
26 3 21 240 203 125
27 3 21 240 203 125
28 3 21 240 203 125
29 3 21 240 203 125
30 3 21 240 203 125
31 3 21 240 203 125
31 9 21 240 203 125
30 9 21 240 203 125
29 9 21 240 203 125
25 31 22 240 203 125
31 7 22 240 203 125
28 9 21 240 203 125
27 9 21 240 203 125
26 9 21 240 203 125
0 4 21 240 203 125
1 4 21 240 203 125
2 4 21 240 203 125
3 4 21 240 203 125
4 4 21 240 203 125
5 4 21 240 203 125
6 4 21 240 203 125
7 4 21 240 203 125
8 4 21 240 203 125
9 4 21 240 203 125
10 4 21 240 203 125
11 4 21 240 203 125
12 4 21 240 203 125
13 4 21 240 203 125
14 4 21 240 203 125
15 4 21 240 203 125
16 4 21 240 203 125
17 4 21 240 203 125
18 4 21 240 203 125
19 4 21 240 203 125
20 4 21 240 203 125
21 4 21 240 203 125
22 4 21 240 203 125
23 4 21 240 203 125
24 4 21 240 203 125
25 4 21 240 203 125
26 4 21 240 203 125
27 4 21 240 203 125
28 4 21 240 203 125
29 4 21 240 203 125
30 4 21 240 203 125
31 4 21 240 203 125
25 9 21 240 203 125
24 9 21 240 203 125
23 9 21 240 203 125
22 9 21 240 203 125
21 9 21 240 203 125
20 9 21 240 203 125
19 9 21 240 203 125
18 9 21 240 203 125
0 5 21 240 203 125
1 5 21 240 203 125
2 5 21 240 203 125
3 5 21 240 203 125
4 5 21 240 203 125
5 5 21 240 203 125
6 5 21 240 203 125
7 5 21 240 203 125
8 5 21 240 203 125
9 5 21 240 203 125
10 5 21 240 203 125
11 5 21 240 203 125
12 5 21 240 203 125
13 5 21 240 203 125
14 5 21 240 203 125
15 5 21 240 203 125
16 5 21 240 203 125
17 5 21 240 203 125
18 5 21 240 203 125
19 5 21 240 203 125
20 5 21 240 203 125
21 5 21 240 203 125
22 5 21 240 203 125
23 5 21 240 203 125
24 5 21 240 203 125
25 5 21 240 203 125
26 5 21 240 203 125
27 5 21 240 203 125
28 5 21 240 203 125
29 5 21 240 203 125
30 5 21 240 203 125
31 5 21 240 203 125
17 9 21 240 203 125
16 9 21 240 203 125
15 9 21 240 203 125
14 9 21 240 203 125
13 9 21 240 203 125
12 9 21 240 203 125
11 9 21 240 203 125
10 9 21 240 203 125
0 6 21 240 203 125
1 6 21 240 203 125
2 6 21 240 203 125
3 6 21 240 203 125
4 6 21 240 203 125
5 6 21 240 203 125
6 6 21 240 203 125
7 6 21 240 203 125
8 6 21 240 203 125
9 6 21 240 203 125
10 6 21 240 203 125
11 6 21 240 203 125
12 6 21 240 203 125
13 6 21 240 203 125
14 6 21 240 203 125
15 6 21 240 203 125
16 6 21 240 203 125
17 6 21 240 203 125
18 6 21 240 203 125
19 6 21 240 203 125
20 6 21 240 203 125
21 6 21 240 203 125
22 6 21 240 203 125
23 6 21 240 203 125
24 6 21 240 203 125
25 6 21 240 203 125
26 6 21 240 203 125
27 6 21 240 203 125
28 6 21 240 203 125
29 6 21 240 203 125
30 6 21 240 203 125
31 6 21 240 203 125
9 9 21 240 203 125
8 9 21 240 203 125
7 9 21 240 203 125
6 9 21 240 203 125
5 9 21 240 203 125
4 9 21 240 203 125
3 9 21 240 203 125
2 9 21 240 203 125
0 7 21 240 203 125
1 7 21 240 203 125
2 7 21 240 203 125
3 7 21 240 203 125
4 7 21 240 203 125
5 7 21 240 203 125
6 7 21 240 203 125
7 7 21 240 203 125
8 7 21 240 203 125
9 7 21 240 203 125
10 7 21 240 203 125
11 7 21 240 203 125
12 7 21 240 203 125
13 7 21 240 203 125
14 7 21 240 203 125
15 7 21 240 203 125
16 7 21 240 203 125
17 7 21 240 203 125
18 7 21 240 203 125
19 7 21 240 203 125
20 7 21 240 203 125
21 7 21 240 203 125
22 7 21 240 203 125
23 7 21 240 203 125
24 7 21 240 203 125
25 7 21 240 203 125
26 7 21 240 203 125
27 7 21 240 203 125
28 7 21 240 203 125
29 7 21 240 203 125
30 7 21 240 203 125
31 7 21 240 203 125
1 9 21 240 203 125
0 9 21 240 203 125
31 8 21 240 203 125
24 31 22 240 203 125
31 6 22 240 203 125
30 8 21 240 203 125
29 8 21 240 203 125
28 8 21 240 203 125
0 8 21 240 203 125
1 8 21 240 203 125
2 8 21 240 203 125
3 8 21 240 203 125
4 8 21 240 203 125
5 8 21 240 203 125
6 8 21 240 203 125
7 8 21 240 203 125
8 8 21 240 203 125
9 8 21 240 203 125
10 8 21 240 203 125
11 8 21 240 203 125
12 8 21 240 203 125
13 8 21 240 203 125
14 8 21 240 203 125
15 8 21 240 203 125
16 8 21 240 203 125
17 8 21 240 203 125
18 8 21 240 203 125
19 8 21 240 203 125
20 8 21 240 203 125
21 8 21 240 203 125
22 8 21 240 203 125
23 8 21 240 203 125
24 8 21 240 203 125
25 8 21 240 203 125
26 8 21 240 203 125
27 8 21 240 203 125
1 0 22 240 203 125
2 0 22 240 203 125
3 0 22 240 203 125
4 0 22 240 203 125
5 0 22 240 203 125
6 0 22 240 203 125
7 0 22 240 203 125
8 0 22 240 203 125
9 0 22 240 203 125
6 9 22 240 203 125
5 9 22 240 203 125
4 9 22 240 203 125
3 9 22 240 203 125
14 0 22 240 203 125
15 0 22 240 203 125
16 0 22 240 203 125
17 0 22 240 203 125
18 0 22 240 203 125
19 0 22 240 203 125
5 7 22 240 203 125
6 7 22 240 203 125
22 0 22 240 203 125
23 0 22 240 203 125
24 0 22 240 203 125
25 0 22 240 203 125
26 0 22 240 203 125
27 0 22 240 203 125
28 0 22 240 203 125
29 0 22 240 203 125
30 0 22 240 203 125
1 1 22 240 203 125
2 1 22 240 203 125
3 1 22 240 203 125
4 1 22 240 203 125
5 1 22 240 203 125
6 1 22 240 203 125
7 1 22 240 203 125
2 9 22 240 203 125
1 9 22 240 203 125
0 9 22 240 203 125
11 1 22 240 203 125
12 1 22 240 203 125
13 1 22 240 203 125
14 1 22 240 203 125
15 1 22 240 203 125
16 1 22 240 203 125
17 1 22 240 203 125
18 1 22 240 203 125
19 1 22 240 203 125
0 8 22 240 203 125
21 1 22 240 203 125
22 1 22 240 203 125
23 1 22 240 203 125
24 1 22 240 203 125
25 1 22 240 203 125
26 1 22 240 203 125
27 1 22 240 203 125
28 1 22 240 203 125
29 1 22 240 203 125
30 1 22 240 203 125
1 2 22 240 203 125
2 2 22 240 203 125
3 2 22 240 203 125
4 2 22 240 203 125
5 2 22 240 203 125
6 2 22 240 203 125
7 2 22 240 203 125
6 8 22 240 203 125
9 2 22 240 203 125
10 2 22 240 203 125
11 2 22 240 203 125
12 2 22 240 203 125
13 2 22 240 203 125
14 2 22 240 203 125
15 2 22 240 203 125
16 2 22 240 203 125
17 2 22 240 203 125
18 2 22 240 203 125
19 2 22 240 203 125
3 6 22 240 203 125
21 2 22 240 203 125
22 2 22 240 203 125
23 2 22 240 203 125
24 2 22 240 203 125
25 2 22 240 203 125
26 2 22 240 203 125
27 2 22 240 203 125
28 2 22 240 203 125
29 2 22 240 203 125
30 2 22 240 203 125
10 27 22 240 203 125
22 31 22 240 203 125
21 31 22 240 203 125
20 31 22 240 203 125
19 31 22 240 203 125
18 31 22 240 203 125
5 8 22 240 203 125
4 8 22 240 203 125
9 3 22 240 203 125
10 3 22 240 203 125
11 3 22 240 203 125
12 3 22 240 203 125
13 3 22 240 203 125
14 3 22 240 203 125
15 3 22 240 203 125
16 3 22 240 203 125
17 3 22 240 203 125
18 3 22 240 203 125
19 3 22 240 203 125
2 6 22 240 203 125
21 3 22 240 203 125
22 3 22 240 203 125
23 3 22 240 203 125
24 3 22 240 203 125
25 3 22 240 203 125
26 3 22 240 203 125
27 3 22 240 203 125
28 3 22 240 203 125
29 3 22 240 203 125
30 3 22 240 203 125
9 27 22 240 203 125
16 31 22 240 203 125
15 31 22 240 203 125
8 28 22 240 203 125
29 25 22 240 203 125
12 31 22 240 203 125
3 8 22 240 203 125
8 27 22 240 203 125
9 4 22 240 203 125
10 4 22 240 203 125
11 4 22 240 203 125
12 4 22 240 203 125
13 4 22 240 203 125
14 4 22 240 203 125
15 4 22 240 203 125
16 4 22 240 203 125
17 4 22 240 203 125
18 4 22 240 203 125
19 4 22 240 203 125
0 7 22 240 203 125
21 4 22 240 203 125
22 4 22 240 203 125
23 4 22 240 203 125
24 4 22 240 203 125
25 4 22 240 203 125
26 4 22 240 203 125
27 4 22 240 203 125
28 4 22 240 203 125
29 4 22 240 203 125
30 4 22 240 203 125
11 31 22 240 203 125
10 31 22 240 203 125
9 31 22 240 203 125
8 31 22 240 203 125
7 31 22 240 203 125
6 31 22 240 203 125
7 5 22 240 203 125
23 29 22 240 203 125
22 29 22 240 203 125
10 5 22 240 203 125
11 5 22 240 203 125
12 5 22 240 203 125
13 5 22 240 203 125
14 5 22 240 203 125
15 5 22 240 203 125
16 5 22 240 203 125
17 5 22 240 203 125
18 5 22 240 203 125
19 5 22 240 203 125
14 31 21 240 203 125
21 5 22 240 203 125
22 5 22 240 203 125
23 5 22 240 203 125
24 5 22 240 203 125
25 5 22 240 203 125
26 5 22 240 203 125
27 5 22 240 203 125
28 5 22 240 203 125
29 5 22 240 203 125
25 26 22 240 203 125
5 31 22 240 203 125
4 31 22 240 203 125
3 31 22 240 203 125
2 31 22 240 203 125
1 31 22 240 203 125
30 30 22 240 203 125
7 6 22 240 203 125
8 6 22 240 203 125
9 6 22 240 203 125
21 29 22 240 203 125
11 6 22 240 203 125
12 6 22 240 203 125
13 6 22 240 203 125
14 6 22 240 203 125
15 6 22 240 203 125
16 6 22 240 203 125
17 6 22 240 203 125
18 6 22 240 203 125
19 6 22 240 203 125
1 8 22 240 203 125
5 5 22 240 203 125
22 6 22 240 203 125
23 6 22 240 203 125
24 6 22 240 203 125
25 6 22 240 203 125
26 6 22 240 203 125
27 6 22 240 203 125
28 6 22 240 203 125
24 26 22 240 203 125
23 26 22 240 203 125
29 30 22 240 203 125
28 30 22 240 203 125
27 30 22 240 203 125
26 30 22 240 203 125
25 30 22 240 203 125
7 27 22 240 203 125
7 7 22 240 203 125
8 7 22 240 203 125
9 7 22 240 203 125
20 29 22 240 203 125
19 29 22 240 203 125
12 7 22 240 203 125
13 7 22 240 203 125
14 7 22 240 203 125
15 7 22 240 203 125
16 7 22 240 203 125
17 7 22 240 203 125
18 7 22 240 203 125
19 7 22 240 203 125
20 7 22 240 203 125
4 5 22 240 203 125
22 7 22 240 203 125
23 7 22 240 203 125
24 7 22 240 203 125
25 7 22 240 203 125
26 7 22 240 203 125
22 26 22 240 203 125
21 26 22 240 203 125
20 26 22 240 203 125
30 7 22 240 203 125
6 27 22 240 203 125
22 30 22 240 203 125
21 30 22 240 203 125
20 30 22 240 203 125
19 30 22 240 203 125
18 30 22 240 203 125
7 8 22 240 203 125
8 8 22 240 203 125
9 8 22 240 203 125
10 8 22 240 203 125
18 29 22 240 203 125
17 29 22 240 203 125
13 8 22 240 203 125
14 8 22 240 203 125
15 8 22 240 203 125
16 8 22 240 203 125
17 8 22 240 203 125
18 8 22 240 203 125
19 8 22 240 203 125
20 8 22 240 203 125
3 5 22 240 203 125
22 8 22 240 203 125
23 8 22 240 203 125
24 8 22 240 203 125
25 8 22 240 203 125
19 26 22 240 203 125
18 26 22 240 203 125
28 8 22 240 203 125
29 8 22 240 203 125
30 8 22 240 203 125
17 30 22 240 203 125
5 27 22 240 203 125
15 30 22 240 203 125
12 26 22 240 203 125
28 25 22 240 203 125
12 30 22 240 203 125
7 9 22 240 203 125
8 9 22 240 203 125
9 9 22 240 203 125
10 9 22 240 203 125
11 9 22 240 203 125
24 28 22 240 203 125
13 9 22 240 203 125
14 9 22 240 203 125
15 9 22 240 203 125
16 9 22 240 203 125
17 9 22 240 203 125
18 9 22 240 203 125
19 9 22 240 203 125
20 9 22 240 203 125
2 5 22 240 203 125
22 9 22 240 203 125
23 9 22 240 203 125
24 9 22 240 203 125
17 26 22 240 203 125
16 26 22 240 203 125
27 9 22 240 203 125
28 9 22 240 203 125
29 9 22 240 203 125
30 9 22 240 203 125
1 10 22 240 203 125
2 10 22 240 203 125
3 10 22 240 203 125
4 10 22 240 203 125
5 10 22 240 203 125
6 10 22 240 203 125
7 10 22 240 203 125
8 10 22 240 203 125
9 10 22 240 203 125
10 10 22 240 203 125
11 10 22 240 203 125
12 10 22 240 203 125
23 28 22 240 203 125
14 10 22 240 203 125
15 10 22 240 203 125
16 10 22 240 203 125
17 10 22 240 203 125
18 10 22 240 203 125
19 10 22 240 203 125
20 10 22 240 203 125
1 5 22 240 203 125
0 5 22 240 203 125
23 10 22 240 203 125
13 27 22 240 203 125
25 10 22 240 203 125
26 10 22 240 203 125
27 10 22 240 203 125
28 10 22 240 203 125
29 10 22 240 203 125
30 10 22 240 203 125
1 11 22 240 203 125
2 11 22 240 203 125
3 11 22 240 203 125
4 11 22 240 203 125
5 11 22 240 203 125
6 11 22 240 203 125
7 11 22 240 203 125
8 11 22 240 203 125
9 11 22 240 203 125
10 11 22 240 203 125
11 11 22 240 203 125
12 11 22 240 203 125
15 28 22 240 203 125
14 11 22 240 203 125
15 11 22 240 203 125
16 11 22 240 203 125
17 11 22 240 203 125
18 11 22 240 203 125
19 11 22 240 203 125
20 11 22 240 203 125
10 30 22 240 203 125
2 8 22 240 203 125
5 4 22 240 203 125
7 28 22 240 203 125
25 11 22 240 203 125
26 11 22 240 203 125
27 11 22 240 203 125
28 11 22 240 203 125
29 11 22 240 203 125
30 11 22 240 203 125
1 12 22 240 203 125
2 12 22 240 203 125
3 12 22 240 203 125
4 12 22 240 203 125
5 12 22 240 203 125
6 12 22 240 203 125
7 12 22 240 203 125
8 12 22 240 203 125
9 12 22 240 203 125
10 12 22 240 203 125
11 12 22 240 203 125
12 12 22 240 203 125
13 29 22 240 203 125
12 29 22 240 203 125
15 12 22 240 203 125
16 12 22 240 203 125
17 12 22 240 203 125
18 12 22 240 203 125
19 12 22 240 203 125
9 30 22 240 203 125
8 30 22 240 203 125
22 12 22 240 203 125
4 4 22 240 203 125
3 4 22 240 203 125
25 12 22 240 203 125
26 12 22 240 203 125
27 12 22 240 203 125
28 12 22 240 203 125
29 12 22 240 203 125
30 12 22 240 203 125
1 13 22 240 203 125
2 13 22 240 203 125
3 13 22 240 203 125
4 13 22 240 203 125
5 13 22 240 203 125
6 13 22 240 203 125
7 13 22 240 203 125
8 13 22 240 203 125
9 13 22 240 203 125
10 13 22 240 203 125
11 13 22 240 203 125
12 13 22 240 203 125
13 13 22 240 203 125
11 29 22 240 203 125
15 13 22 240 203 125
16 13 22 240 203 125
17 13 22 240 203 125
18 13 22 240 203 125
7 30 22 240 203 125
6 30 22 240 203 125
21 13 22 240 203 125
22 13 22 240 203 125
23 13 22 240 203 125
2 4 22 240 203 125
1 4 22 240 203 125
26 13 22 240 203 125
27 13 22 240 203 125
28 13 22 240 203 125
29 13 22 240 203 125
30 13 22 240 203 125
1 14 22 240 203 125
2 14 22 240 203 125
3 14 22 240 203 125
4 14 22 240 203 125
5 14 22 240 203 125
6 14 22 240 203 125
7 14 22 240 203 125
8 14 22 240 203 125
9 14 22 240 203 125
10 14 22 240 203 125
5 30 22 240 203 125
4 30 22 240 203 125
3 30 22 240 203 125
10 29 22 240 203 125
15 14 22 240 203 125
2 30 22 240 203 125
1 30 22 240 203 125
30 29 22 240 203 125
29 29 22 240 203 125
20 14 22 240 203 125
21 14 22 240 203 125
22 14 22 240 203 125
23 14 22 240 203 125
24 14 22 240 203 125
0 4 22 240 203 125
6 3 22 240 203 125
5 3 22 240 203 125
28 14 22 240 203 125
29 14 22 240 203 125
30 14 22 240 203 125
1 15 22 240 203 125
2 15 22 240 203 125
3 15 22 240 203 125
4 15 22 240 203 125
5 15 22 240 203 125
6 15 22 240 203 125
7 15 22 240 203 125
8 15 22 240 203 125
8 29 22 240 203 125
7 29 22 240 203 125
12 27 22 240 203 125
12 15 22 240 203 125
28 29 22 240 203 125
27 29 22 240 203 125
26 29 22 240 203 125
4 27 22 240 203 125
17 15 22 240 203 125
18 15 22 240 203 125
19 15 22 240 203 125
20 15 22 240 203 125
21 15 22 240 203 125
22 15 22 240 203 125
23 15 22 240 203 125
24 15 22 240 203 125
25 15 22 240 203 125
26 15 22 240 203 125
4 3 22 240 203 125
3 3 22 240 203 125
29 15 22 240 203 125
30 15 22 240 203 125
1 16 22 240 203 125
2 16 22 240 203 125
3 16 22 240 203 125
4 16 22 240 203 125
5 16 22 240 203 125
6 16 22 240 203 125
7 16 22 240 203 125
6 29 22 240 203 125
5 29 22 240 203 125
10 16 22 240 203 125
11 16 22 240 203 125
12 16 22 240 203 125
13 16 22 240 203 125
14 16 22 240 203 125
15 16 22 240 203 125
16 16 22 240 203 125
17 16 22 240 203 125
18 16 22 240 203 125
19 16 22 240 203 125
20 16 22 240 203 125
21 16 22 240 203 125
22 16 22 240 203 125
23 16 22 240 203 125
24 16 22 240 203 125
25 16 22 240 203 125
26 16 22 240 203 125
27 16 22 240 203 125
2 3 22 240 203 125
1 3 22 240 203 125
30 16 22 240 203 125
1 17 22 240 203 125
2 17 22 240 203 125
3 17 22 240 203 125
4 17 22 240 203 125
4 29 22 240 203 125
3 29 22 240 203 125
2 29 22 240 203 125
30 31 22 240 203 125
9 17 22 240 203 125
10 17 22 240 203 125
11 17 22 240 203 125
12 17 22 240 203 125
13 17 22 240 203 125
14 17 22 240 203 125
15 17 22 240 203 125
16 17 22 240 203 125
17 17 22 240 203 125
18 17 22 240 203 125
19 17 22 240 203 125
20 17 22 240 203 125
21 17 22 240 203 125
22 17 22 240 203 125
23 17 22 240 203 125
24 17 22 240 203 125
25 17 22 240 203 125
26 17 22 240 203 125
27 17 22 240 203 125
4 28 22 240 203 125
0 3 22 240 203 125
11 30 22 240 203 125
1 18 22 240 203 125
1 29 22 240 203 125
30 28 22 240 203 125
29 28 22 240 203 125
5 18 22 240 203 125
6 18 22 240 203 125
22 28 22 240 203 125
8 18 22 240 203 125
9 18 22 240 203 125
10 18 22 240 203 125
11 18 22 240 203 125
12 18 22 240 203 125
13 18 22 240 203 125
14 18 22 240 203 125
15 18 22 240 203 125
16 18 22 240 203 125
17 18 22 240 203 125
18 18 22 240 203 125
19 18 22 240 203 125
20 18 22 240 203 125
21 18 22 240 203 125
22 18 22 240 203 125
23 18 22 240 203 125
24 18 22 240 203 125
25 18 22 240 203 125
26 18 22 240 203 125
3 28 22 240 203 125
2 28 22 240 203 125
29 18 22 240 203 125
30 18 22 240 203 125
28 28 22 240 203 125
27 28 22 240 203 125
3 19 22 240 203 125
4 19 22 240 203 125
5 19 22 240 203 125
6 19 22 240 203 125
21 28 22 240 203 125
20 28 22 240 203 125
9 19 22 240 203 125
10 19 22 240 203 125
11 19 22 240 203 125
12 19 22 240 203 125
13 19 22 240 203 125
14 19 22 240 203 125
15 19 22 240 203 125
16 19 22 240 203 125
17 19 22 240 203 125
18 19 22 240 203 125
19 19 22 240 203 125
20 19 22 240 203 125
21 19 22 240 203 125
22 19 22 240 203 125
23 19 22 240 203 125
24 19 22 240 203 125
25 19 22 240 203 125
26 19 22 240 203 125
1 28 22 240 203 125
28 19 22 240 203 125
29 19 22 240 203 125
30 19 22 240 203 125
1 20 22 240 203 125
2 20 22 240 203 125
3 20 22 240 203 125
4 20 22 240 203 125
5 20 22 240 203 125
6 20 22 240 203 125
7 20 22 240 203 125
19 28 22 240 203 125
18 28 22 240 203 125
10 20 22 240 203 125
11 20 22 240 203 125
12 20 22 240 203 125
13 20 22 240 203 125
14 20 22 240 203 125
15 20 22 240 203 125
16 20 22 240 203 125
17 20 22 240 203 125
18 20 22 240 203 125
19 20 22 240 203 125
20 20 22 240 203 125
21 20 22 240 203 125
22 20 22 240 203 125
23 20 22 240 203 125
24 20 22 240 203 125
25 20 22 240 203 125
30 27 22 240 203 125
29 27 22 240 203 125
28 20 22 240 203 125
29 20 22 240 203 125
30 20 22 240 203 125
1 21 22 240 203 125
2 21 22 240 203 125
3 21 22 240 203 125
4 21 22 240 203 125
5 21 22 240 203 125
6 21 22 240 203 125
7 21 22 240 203 125
8 21 22 240 203 125
17 28 22 240 203 125
16 28 22 240 203 125
11 21 22 240 203 125
12 21 22 240 203 125
13 21 22 240 203 125
14 21 22 240 203 125
15 21 22 240 203 125
16 21 22 240 203 125
17 21 22 240 203 125
18 21 22 240 203 125
19 21 22 240 203 125
20 21 22 240 203 125
21 21 22 240 203 125
22 21 22 240 203 125
23 21 22 240 203 125
24 21 22 240 203 125
28 27 22 240 203 125
27 27 22 240 203 125
27 21 22 240 203 125
28 21 22 240 203 125
29 21 22 240 203 125
30 21 22 240 203 125
1 22 22 240 203 125
2 22 22 240 203 125
3 22 22 240 203 125
4 22 22 240 203 125
5 22 22 240 203 125
6 22 22 240 203 125
7 22 22 240 203 125
8 22 22 240 203 125
9 22 22 240 203 125
13 28 22 240 203 125
12 28 22 240 203 125
12 22 22 240 203 125
13 22 22 240 203 125
14 22 22 240 203 125
15 22 22 240 203 125
16 22 22 240 203 125
17 22 22 240 203 125
18 22 22 240 203 125
19 22 22 240 203 125
20 22 22 240 203 125
21 22 22 240 203 125
22 22 22 240 203 125
3 27 22 240 203 125
2 27 22 240 203 125
25 27 22 240 203 125
26 22 22 240 203 125
27 22 22 240 203 125
28 22 22 240 203 125
29 22 22 240 203 125
30 22 22 240 203 125
1 23 22 240 203 125
2 23 22 240 203 125
3 23 22 240 203 125
4 23 22 240 203 125
5 23 22 240 203 125
6 23 22 240 203 125
7 23 22 240 203 125
8 23 22 240 203 125
9 23 22 240 203 125
15 29 22 240 203 125
11 28 22 240 203 125
12 23 22 240 203 125
13 23 22 240 203 125
14 23 22 240 203 125
15 23 22 240 203 125
16 23 22 240 203 125
17 23 22 240 203 125
18 23 22 240 203 125
19 23 22 240 203 125
20 23 22 240 203 125
24 27 22 240 203 125
23 27 22 240 203 125
22 27 22 240 203 125
21 27 22 240 203 125
25 23 22 240 203 125
26 23 22 240 203 125
27 23 22 240 203 125
28 23 22 240 203 125
29 23 22 240 203 125
30 23 22 240 203 125
1 24 22 240 203 125
2 24 22 240 203 125
3 24 22 240 203 125
4 24 22 240 203 125
17 31 22 240 203 125
16 30 22 240 203 125
16 29 22 240 203 125
14 27 21 240 203 125
11 26 22 240 203 125
10 24 22 240 203 125
11 24 22 240 203 125
10 28 22 240 203 125
13 24 22 240 203 125
14 24 22 240 203 125
15 24 22 240 203 125
16 24 22 240 203 125
17 24 22 240 203 125
20 27 22 240 203 125
19 27 22 240 203 125
18 27 22 240 203 125
17 27 22 240 203 125
22 24 22 240 203 125
23 24 22 240 203 125
1 27 22 240 203 125
7 26 22 240 203 125
26 24 22 240 203 125
27 24 22 240 203 125
28 24 22 240 203 125
29 24 22 240 203 125
30 24 22 240 203 125
1 25 22 240 203 125
2 25 22 240 203 125
10 26 22 240 203 125
9 26 22 240 203 125
8 26 22 240 203 125
6 25 22 240 203 125
7 25 22 240 203 125
8 25 22 240 203 125
9 25 22 240 203 125
10 25 22 240 203 125
11 25 22 240 203 125
12 25 22 240 203 125
9 28 22 240 203 125
14 25 22 240 203 125
16 27 22 240 203 125
15 27 22 240 203 125
6 28 22 240 203 125
18 25 22 240 203 125
19 25 22 240 203 125
20 25 22 240 203 125
21 25 22 240 203 125
22 25 22 240 203 125
8 17 22 240 203 125
24 25 22 240 203 125
25 25 22 240 203 125
13 15 21 240 203 125
8 19 22 44 110 8
8 19 23 44 110 8
8 19 24 44 110 8
7 20 23 44 110 8
8 18 25 44 110 8
8 20 25 44 110 8
20 12 22 44 110 8
20 12 23 44 110 8
20 12 24 44 110 8
20 12 25 44 110 8
21 12 22 44 110 8
22 12 23 44 110 8
29 26 21 240 203 125
29 26 22 44 110 8
29 26 23 44 110 8
29 26 24 44 110 8
8 3 22 44 110 8
8 3 23 44 110 8
7 2 24 44 110 8
